Workbook

Sheet Workbook Overview
B2: Workbook Overview
B3: EXL Cloud Training Workbook — Management Reporting with Dynamic Arrays
B5: # | C5: Sheet Name | D5: Section | E5: Description | F5: Type | G5: Status
B7: Navigation & Reference (2 sheets)
B8: 1 | C8: {=MID(CELL("filename",'Workbook Overview'!A1),FIND("]",CELL("filename",'Workbook Overview'!A1))+1,255)} -> Workbook Overview | D8: Navigation | E8: Table of contents with section grouping and sheet descriptions | F8: Navigation | G8: Active
B9: =B8+1 -> 2 | C9: {=MID(CELL("filename",'Read Me'!A1),FIND("]",CELL("filename",'Read Me'!A1))+1,255)} -> Read Me | D9: Navigation | E9: Purpose, data structure, import methods, session steps, usage instructions | F9: Documentation | G9: Active
B11: Source Data & Engine (4 sheets)
B12: =B9+1 -> 3 | C12: {=MID(CELL("filename",'Fact_Financials- OG'!A1),FIND("]",CELL("filename",'Fact_Financials- OG'!A1))+1,255)} -> Fact_Financials- OG | D12: Source | E12: Original source data — unchanged baseline from data system | F12: Data Source | G12: Baseline
B13: =B12+1 -> 4 | C13: {=MID(CELL("filename",'Fact_Financials- New'!A1),FIND("]",CELL("filename",'Fact_Financials- New'!A1))+1,255)} -> Fact_Financials- New | D13: Source | E13: Working copy with tbl_Financials — Jul 2026 actuals rolled in; Aug–Dec 2026 zeroed for forecast | F13: Data Source | G13: Active
B14: =B13+1 -> 5 | C14: {=MID(CELL("filename",'Fact_Financials- Rolled Act'!A1),FIND("]",CELL("filename",'Fact_Financials- Rolled Act'!A1))+1,255)} -> Fact_Financials- Rolled Act | D14: Source | E14: Roll-forward copy — Jul 2026 actuals retained, Aug–Dec zeroed | F14: Data Source | G14: Active
B15: =B14+1 -> 6 | C15: {=MID(CELL("filename",'Dynamic Extracts'!A1),FIND("]",CELL("filename",'Dynamic Extracts'!A1))+1,255)} -> Dynamic Extracts | D15: Engine | E15: UNIQUE dimension lists, named LAMBDAs (PLSTRUCTURE/PLDATA/PLDATABY), tAccountMap lookup | F15: Engine | G15: Active
C17: Summary by Section | D17: Sheets
C18: Navigation & Reference | D18: 2
C19: Source Data & Engine | D19: 4
C20: Total Sheets | D20: =SUM(D18:D19) -> 6

Sheet Read Me
B2: Finance Data — Management Reporting Dataset
B3: Fictional sample data for the 'Practical Claude AI for Finance Professionals' training series. | E3: ScenarioKey | F3: Scenario | G3: ScenarioOrder
E4: 1 | F4: Actual | G4: 1
B5: ABOUT THIS WORKBOOK | E5: 2 | F5: Budget | G5: 2
B6: A ready-to-import star schema: one fact table and one dimension table. All figures are synthetic | E6: 3 | F6: Forecast | G6: 3
B7: and generated for teaching purposes only — they do not represent any real company or person.
B9: DATA STRUCTURE
B10: Fact_Financials (OG) — 7,812 rows. Original dataset — do not modify.
B11: Fact_Financials (New) — 7,812 rows. Working copy for the session.
B12: Dim_Scenario — Scenario lookup table (see right →)
B14: Columns:
B15: DateKey | EntityKey | AccountKey | DeptKey | ScenarioKey | Amount
B17: Coverage:
B18: • 36 months: Jan 2024 – Dec 2026 (3 full years)
B19: • 3 entities: Americas, EMEA, APAC
B20: • 8 accounts: Product Revenue, Services Revenue, COGS, Salaries & Wages, Marketing, Software & Tools, T&E, Other OpEx
B21: • 5 departments: Sales, Marketing, Operations, Finance, Research & Development
... B84: Important context about this workbook: The sheet 'Fact_Financials- New' has 7,812 rows of financial fact data in B3:G7815 (headers in B3:G3). Columns: DateKey (YYYYMMDD integer e.g. 20240131), EntityKey (Americas / EMEA / APAC), AccountKey (Product Revenue, Services Revenue, COGS, Salaries & Wages, Marketing, Software & Tools, T&E, Other OpEx), DeptKey (Sales, Marketing, Operations, Finance, R&D), ScenarioKey (1=Actual, 2=Budget, 3=Forecast), Amount (positive=revenue, negative=expense). Column A is blank margin. Net Profit = SUM(Amount) with no sign flip. Coverage: 36 months (Jan 2024 – Dec 2026), 3 entities, 8 accounts, 5 departments, 3 scenarios. Task — Build Dynamic Array extractions and LAMBDA functions: Create a new sheet called Dynamic Extracts and build the following using only dynamic array formulas (FILTER, SORT, UNIQUE, SORTBY) referencing the raw data on Fact_Financials- New. Do NOT convert the source to a Table first. Use range references B3:G7815. Build these specific extractions: 1. Unique dimension lists — Use UNIQUE() to extract each dimension into its own labelled column: - All unique EntityKey values (should return 3) - All unique AccountKey values (should return 8) - All unique DeptKey values (should return 5) - All unique DateKey values sorted ascending (should return 36) 2. Filtered subsets — Build FILTER() formulas for: - All Actuals only (ScenarioKey=1) — this should spill approximately 2,604 rows - All Actuals for Americas only (ScenarioKey=1 AND EntityKey="Americas") - Revenue accounts only (AccountKey contains "Revenue") across all scenarios - A specific month extract: e.g. Jan 2024 Actuals (DateKey=20240131, ScenarioKey=1) 3. Named LAMBDA functions — Register these as named functions in Name Manager (Formulas → Name Manager) so they are reusable: - GETSCENARIO(scenario_key) — returns all rows for a given ScenarioKey - GETENTITY(entity_name) — returns all rows for a given EntityKey - GETPERIOD(date_key, scenario_key) — returns all rows for a specific period and scenario - PLSUMMARY(entity, scenario) — returns a summarised P&L (one row per AccountKey with summed Amount) for a given entity and scenario across all periods 4. Best practice notes — Add a header block at the top of the sheet explaining: - Dynamic arrays spill automatically — do not put anything below or to the right of a spill range - These formulas recalculate live — any change to the source data flows through instantly - LAMBDAs are reusable across the entire workbook once registered - Trade-off vs Table: no auto-expand on new rows, but more flexible for ad-hoc slicing - Performance consideration: FILTER() over 7,812 rows is fine, but would degrade at 100k+ 5. Validation — Add a small check block confirming: - ROWS(Actuals filter) + ROWS(Budget filter) + ROWS(Forecast filter) = 7,812 - SUM of filtered Actuals Amount = SUM of SUMIFS against source for ScenarioKey=1

Sheet Fact_Financials- OG
B2: Fact_Financials — Original (Do Not Modify)
B3: DateKey | C3: EntityKey | D3: AccountKey | E3: DeptKey | F3: ScenarioKey | G3: Amount
B4: 20240131 | C4: Americas | D4: Product Revenue | E4: Sales | F4: 1 | G4: 656646
B5: 20240131 | C5: Americas | D5: Product Revenue | E5: Sales | F5: 2 | G5: 671674
B6: 20240131 | C6: Americas | D6: Product Revenue | E6: Marketing | F6: 1 | G6: 101505
B7: 20240131 | C7: Americas | D7: Product Revenue | E7: Marketing | F7: 2 | G7: 111946
B8: 20240131 | C8: Americas | D8: Product Revenue | E8: Operations | F8: 1 | G8: 314202
B9: 20240131 | C9: Americas | D9: Product Revenue | E9: Operations | F9: 2 | G9: 335837
B10: 20240131 | C10: EMEA | D10: Product Revenue | E10: Sales | F10: 1 | G10: 444010
B11: 20240131 | C11: EMEA | D11: Product Revenue | E11: Sales | F11: 2 | G11: 477635
B12: 20240131 | C12: EMEA | D12: Product Revenue | E12: Marketing | F12: 1 | G12: 78716
B13: 20240131 | C13: EMEA | D13: Product Revenue | E13: Marketing | F13: 2 | G13: 79606
B14: 20240131 | C14: EMEA | D14: Product Revenue | E14: Operations | F14: 1 | G14: 234501
B15: 20240131 | C15: EMEA | D15: Product Revenue | E15: Operations | F15: 2 | G15: 238817
... B7815: 20261231 | C7815: APAC | D7815: Other Operating Expenses | E7815: Operations | F7815: 3 | G7815: -15066

Sheet Fact_Financials- New
B2: Fact_Financials — Working Copy
B3: DateKey | C3: EntityKey | D3: AccountKey | E3: DeptKey | F3: ScenarioKey | G3: Amount
B4: 20240131 | C4: Americas | D4: Product Revenue | E4: Sales | F4: 1 | G4: 656646
B5: 20240131 | C5: Americas | D5: Product Revenue | E5: Sales | F5: 2 | G5: 671674
B6: 20240131 | C6: Americas | D6: Product Revenue | E6: Marketing | F6: 1 | G6: 101505
B7: 20240131 | C7: Americas | D7: Product Revenue | E7: Marketing | F7: 2 | G7: 111946
B8: 20240131 | C8: Americas | D8: Product Revenue | E8: Operations | F8: 1 | G8: 314202
B9: 20240131 | C9: Americas | D9: Product Revenue | E9: Operations | F9: 2 | G9: 335837
B10: 20240131 | C10: EMEA | D10: Product Revenue | E10: Sales | F10: 1 | G10: 444010
B11: 20240131 | C11: EMEA | D11: Product Revenue | E11: Sales | F11: 2 | G11: 477635
B12: 20240131 | C12: EMEA | D12: Product Revenue | E12: Marketing | F12: 1 | G12: 78716
B13: 20240131 | C13: EMEA | D13: Product Revenue | E13: Marketing | F13: 2 | G13: 79606
B14: 20240131 | C14: EMEA | D14: Product Revenue | E14: Operations | F14: 1 | G14: 234501
B15: 20240131 | C15: EMEA | D15: Product Revenue | E15: Operations | F15: 2 | G15: 238817
... B7815: 20261231 | C7815: APAC | D7815: Other Operating Expenses | E7815: Operations | F7815: 3 | G7815: -15066

Sheet Fact_Financials- Rolled Act
B2: Fact_Financials — Rolled Actuals
B3: DateKey | C3: EntityKey | D3: AccountKey | E3: DeptKey | F3: ScenarioKey | G3: Amount
B4: 20240131 | C4: Americas | D4: Product Revenue | E4: Sales | F4: 1 | G4: 656646
B5: 20240131 | C5: Americas | D5: Product Revenue | E5: Sales | F5: 2 | G5: 671674
B6: 20240131 | C6: Americas | D6: Product Revenue | E6: Marketing | F6: 1 | G6: 101505
B7: 20240131 | C7: Americas | D7: Product Revenue | E7: Marketing | F7: 2 | G7: 111946
B8: 20240131 | C8: Americas | D8: Product Revenue | E8: Operations | F8: 1 | G8: 314202
B9: 20240131 | C9: Americas | D9: Product Revenue | E9: Operations | F9: 2 | G9: 335837
B10: 20240131 | C10: EMEA | D10: Product Revenue | E10: Sales | F10: 1 | G10: 444010
B11: 20240131 | C11: EMEA | D11: Product Revenue | E11: Sales | F11: 2 | G11: 477635
B12: 20240131 | C12: EMEA | D12: Product Revenue | E12: Marketing | F12: 1 | G12: 78716
B13: 20240131 | C13: EMEA | D13: Product Revenue | E13: Marketing | F13: 2 | G13: 79606
B14: 20240131 | C14: EMEA | D14: Product Revenue | E14: Operations | F14: 1 | G14: 234501
B15: 20240131 | C15: EMEA | D15: Product Revenue | E15: Operations | F15: 2 | G15: 238817
... B7815: 20261231 | C7815: APAC | D7815: Other Operating Expenses | E7815: Operations | F7815: 3 | G7815: -15066

Sheet Dynamic Extracts
B2: Dynamic Extracts
B3: Dynamic array formulas (FILTER, SORT, UNIQUE) and named LAMBDA functions referencing Fact_Financials- New.
B5: BEST PRACTICES
B6: • Dynamic arrays spill automatically — do not put anything below or to the right of a spill range.
B7: • These formulas recalculate live — any change to the source data on Fact_Financials- New flows through instantly.
B8: • LAMBDAs are reusable across the entire workbook once registered in Name Manager (Formulas → Name Manager).
B9: • Trade-off vs Table: no auto-expand on new rows, but more flexible for ad-hoc slicing without creating pivot tables.
B10: • Performance: FILTER() over 7,812 rows is fast. Above 100k+ rows, consider Power Query or pivot tables instead.
B12: 1. UNIQUE DIMENSION LISTS | J12: 3. NAMED LAMBDA FUNCTIONS (3 Active)
B13: EntityKey | D13: AccountKey | F13: DeptKey | H13: DateKey (sorted) | J13: Function | K13: Syntax | L13: Description
B14: {=_xlfn._xlws.SORT(_xlfn.UNIQUE('Fact_Financials- New'!C4:C7815))} -> Americas | D14: {=_xlfn._xlws.SORT(_xlfn.UNIQUE('Fact_Financials- New'!D4:D7815))} -> Cost of Goods Sold | F14: {=_xlfn._xlws.SORT(_xlfn.UNIQUE('Fact_Financials- New'!E4:E7815))} -> Finance | H14: {=_xlfn._xlws.SORT(_xlfn.UNIQUE('Fact_Financials- New'!B4:B7815))} -> 20240131 | J14: PLSTRUCTURE | K14: =PLSTRUCTURE() | L14: Builds P&L row labels dynamically from tAccountMap: Revenue accounts → Total Revenue → COGS → Gross Profit → OpEx → Total OpEx → Net Profit. Used as the label spine for every P&L block.
B15: APAC | D15: Marketing & Advertising | F15: Marketing | H15: 20240229 | J15: PLDATA | K15: =PLDATA(dates, scenario) | L15: Group-level P&L data block. Returns a MAKEARRAY (n×m) of amounts for all accounts × all dates. Subtotals (Total Revenue, Gross Profit, Total OpEx, Net Profit) computed from source via SUMPRODUCT.
B16: EMEA | D16: Other Operating Expenses | F16: Operations | H16: 20240331 | J16: PLDATABY | K16: =PLDATABY(dates, scenario, entity) | L16: Entity-level P&L data block. Same as PLDATA but adds an EntityKey filter. Entity name should come from a cell reference, not hardcoded.
D17: Product Revenue | F17: Research & Development | H17: 20240430
D18: Salaries & Wages | F18: Sales | H18: 20240531
D19: Services Revenue | H19: 20240630
D20: Software & Tools | H20: 20240731
D21: Travel & Entertainment | H21: 20240831
H22: 20240930
H23: 20241031
H24: 20241130 | J24: 5. P&L ACCOUNT MAP
H25: 20241231 | J25: Controls the dynamic P&L structure. Add a row here → report auto-expands.
H26: 20250131
H27: 20250228 | J27: AccountKey | K27: Category | L27: SortOrder
H28: 20250331 | J28: Product Revenue | K28: Revenue | L28: 1
H29: 20250430 | J29: Services Revenue | K29: Revenue | L29: 2
H30: 20250531 | J30: Cost of Goods Sold | K30: COGS | L30: 3
H31: 20250630 | J31: Salaries & Wages | K31: OpEx | L31: 4
H32: 20250731 | J32: Marketing & Advertising | K32: OpEx | L32: 5
H33: 20250831 | J33: Software & Tools | K33: OpEx | L33: 6
H34: 20250930 | J34: Travel & Entertainment | K34: OpEx | L34: 7
H35: 20251031 | J35: Other Operating Expenses | K35: OpEx | L35: 8
H36: 20251130
H37: 20251231
H38: 20260131
H39: 20260228
H40: 20260331
H41: 20260430
H42: 20260531
H43: 20260630
...

Sheet Change Log
A1: Date | B1: Changed By | C1: Sheet(s) Affected | D1: Change Description | E1: Reason
A2: 46195 | B2: Claude | C2: Workbook Overview, Claude Log, Change Log | D2: Refreshed Workbook Overview from 17 stale sheets to 6 actual sheets (2 sections). Created Claude Log and Change Log sheets. | E2: User requested /workbook-overview refresh — many sheets listed in TOC no longer exist in workbook

Sheet Claude Log
A1: Turn # | B1: Date | C1: User Request | D1: Action Taken | E1: Details | F1: Outcome
A2: 1 | B2: 46195 | C2: Refresh the Workbook Overview using /workbook-overview skill | D2: Cleared stale 17-sheet TOC, rebuilt to match actual 6 sheets across 2 sections | E2: Cleared rows 7-43. Rebuilt with Navigation & Reference (2 sheets: Workbook Overview, Read Me) and Source Data & Engine (4 sheets: OG, New, Rolled Act, Dynamic Extracts). Used CELL("filename") formulas for dynamic sheet names, sequential counter formulas, yellow input cells for Section/Description/Type. Applied alternating banding, row grouping, summary block with SUM formula. Created Claude Log and Change Log sheets. | F2: Workbook Overview now shows 6 actual sheets in 2 collapsible sections. All formulas verified. Summary total = 6.
